Workbook

Sheet Hoja1
A2: Padre | B2: ssets
A3: Office adm | B3: Office rooms / facilities | C3: =_xlfn.TRANSLATE(B3,"en","es") -> Oficinas / instalaciones | E3: =LEN(C3) -> 24
A4: Office adm | B4: Production facilities | C4: =_xlfn.TRANSLATE(B4,"en","es") -> Instalaciones de producción | E4: =LEN(C4) -> 27
A5: Office adm | B5: Infrastructure cabling (e.g., electrical, grounding, etc.) | C5: =_xlfn.TRANSLATE(B5,"en","es") -> Cableado de infraestructuras (por ejemplo, eléctrico, de puesta a tierra, etc.) | E5: =LEN(C5) -> 79
A6: Office adm | B6: Basic services (e.g., electricity, water, sewer, HVAC, air-conditioning, fire suppression, etc.) | C6: =_xlfn.TRANSLATE(B6,"en","es") -> Servicios básicos (por ejemplo, electricidad, agua, alcantarillado, climatización, aire acondicionado, supresión de incendios, etc.) | E6: =LEN(C6) -> 132
A7: Office adm | B7: Server room or datacenter | C7: =_xlfn.TRANSLATE(B7,"en","es") -> Sala de servidores o centro de datos | E7: =LEN(C7) -> 36
A8: Office adm | B8: Remote workspace | C8: =_xlfn.TRANSLATE(B8,"en","es") -> Espacio de trabajo remoto | E8: =LEN(C8) -> 25
A9: Office adm | B9: Archives | C9: =_xlfn.TRANSLATE(B9,"en","es") -> Archivos | E9: =LEN(C9) -> 8
A10: Office adm | B10: Warehouses | C10: =_xlfn.TRANSLATE(B10,"en","es") -> Almacenes | E10: =LEN(C10) -> 9
A11: Office adm | B11: Safes | C11: =_xlfn.TRANSLATE(B11,"en","es") -> Cajas fuertes | E11: =LEN(C11) -> 13
A12: Office adm | B12: Cabinets | C12: =_xlfn.TRANSLATE(B12,"en","es") -> Gabinetes | E12: =LEN(C12) -> 9
A13: Office adm | B13: Uniterruptible power supply (UPS) devices | C13: =_xlfn.TRANSLATE(B13,"en","es") -> Dispositivos de alimentación unitrrumpible (SAI) | E13: =LEN(C13) -> 48
A14: Office adm | B14: Power generators | C14: =_xlfn.TRANSLATE(B14,"en","es") -> Generadores eléctricos | E14: =LEN(C14) -> 22
... A19: Office adm | B19: Cards and card readers | C19: =_xlfn.TRANSLATE(B19,"en","es") -> Tarjetas y lectores de tarjetas | E19: =LEN(C19) -> 31
B20: IT and communication equipment | C20: =_xlfn.TRANSLATE(B20,"en","es") -> Equipos de TI y comunicaciones | E20: =LEN(C20) -> 30
B21: Assets | C21: =_xlfn.TRANSLATE(B21,"en","es") -> Activos | E21: =LEN(C21) -> 7
A22: IT and communication equipment | B22: Desktop computers | C22: =_xlfn.TRANSLATE(B22,"en","es") -> Ordenadores de sobremesa | E22: =LEN(C22) -> 24
A23: IT and communication equipment | B23: IT cabling (e.g., coaxial, fiber, ethernet, etc.) | C23: =_xlfn.TRANSLATE(B23,"en","es") -> Cableado IT (por ejemplo, coaxial, fibra, ethernet, etc.) | E23: =LEN(C23) -> 57
A24: IT and communication equipment | B24: Servers | C24: =_xlfn.TRANSLATE(B24,"en","es") -> Servidores | E24: =LEN(C24) -> 10
A25: IT and communication equipment | B25: Measuring equipment | C25: =_xlfn.TRANSLATE(B25,"en","es") -> Equipos de medición | E25: =LEN(C25) -> 19
A26: IT and communication equipment | B26: Desktop phones | C26: =_xlfn.TRANSLATE(B26,"en","es") -> Teléfonos de sobremesa | E26: =LEN(C26) -> 22
A27: IT and communication equipment | B27: Wireless WAN (includes WAN assets plus wi-fi and/or bluetooth, routers, adapters, access points, etc.) | C27: =_xlfn.TRANSLATE(B27,"en","es") -> WAN inalámbrico (incluye activos WAN además de wi-fi y/o bluetooth, routers, adaptadores, puntos de acceso, etc.) | E27: =LEN(C27) -> 113
A28: IT and communication equipment | B28: Wireless LAN (includes wi-fi and/or bluetooth, routers, adapters, access points, etc.) | C28: =_xlfn.TRANSLATE(B28,"en","es") -> LAN inalámbrica (incluye wi-fi y/o bluetooth, routers, adaptadores, puntos de acceso, etc.) | E28: =LEN(C28) -> 91
A29: IT and communication equipment | B29: Storage media | C29: =_xlfn.TRANSLATE(B29,"en","es") -> Medios de almacenamiento | E29: =LEN(C29) -> 24
A30: IT and communication equipment | B30: Printers, faxes, scanners, photocopiers and other peripherals | C30: =_xlfn.TRANSLATE(B30,"en","es") -> Impresoras, faxes, escáneres, fotocopiadoras y otros periféricos | E30: =LEN(C30) -> 64
A31: IT and communication equipment | B31: Network equipment (e.g., firewalls, routers and switches) | C31: =_xlfn.TRANSLATE(B31,"en","es") -> Equipos de red (por ejemplo, cortafuegos, routers y switches) | E31: =LEN(C31) -> 61
A32: IT and communication equipment | B32: Mobile devices (e.g., laptops, notebooks, tablets, smartphones, PDAs) | C32: =_xlfn.TRANSLATE(B32,"en","es") -> Dispositivos móviles (por ejemplo, portátiles, portátiles, tabletas, smartphones, PDAs) | E32: =LEN(C32) -> 87
B33: Software & databases | C33: =_xlfn.TRANSLATE(B33,"en","es") -> Software y bases de datos | E33: =LEN(C33) -> 25
B34: Assets | C34: =_xlfn.TRANSLATE(B34,"en","es") -> Activos | E34: =LEN(C34) -> 7
A35: Software & databases | B35: Databases | C35: =_xlfn.TRANSLATE(B35,"en","es") -> Bases de datos | E35: =LEN(C35) -> 14
A36: Software & databases | B36: Various software tools | C36: =_xlfn.TRANSLATE(B36,"en","es") -> Diversas herramientas de software | E36: =LEN(C36) -> 33
A37: Software & databases | B37: Database management systems | C37: =_xlfn.TRANSLATE(B37,"en","es") -> Sistemas de gestión de bases de datos | E37: =LEN(C37) -> 37
A38: Software & databases | B38: Operating systems | C38: =_xlfn.TRANSLATE(B38,"en","es") -> Sistemas operativos | E38: =LEN(C38) -> 19
A39: Software & databases | B39: Third-party custom made software | C39: =_xlfn.TRANSLATE(B39,"en","es") -> Software personalizado de terceros | E39: =LEN(C39) -> 34
A40: Software & databases | B40: Internally developed software | C40: =_xlfn.TRANSLATE(B40,"en","es") -> Software desarrollado internamente | E40: =LEN(C40) -> 34
A41: Software & databases | B41: Third-party off-the-shelf applications (e.g., office suite) | C41: =_xlfn.TRANSLATE(B41,"en","es") -> Aplicaciones de terceros listas para usar (por ejemplo, suite de oficina) | E41: =LEN(C41) -> 73
B42: Other documents and data (in electronic and other forms) | C42: =_xlfn.TRANSLATE(B42,"en","es") -> Otros documentos y datos (en formatos electrónicos y otros)
B43: Assets | C43: =_xlfn.TRANSLATE(B43,"en","es") -> Activos
A44: Other documents and data (in electronic and other forms) | B44: Equipment documentation | C44: =_xlfn.TRANSLATE(B44,"en","es") -> Documentación del equipo
A45: Other documents and data (in electronic and other forms) | B45: Records and logs | C45: =_xlfn.TRANSLATE(B45,"en","es") -> Registros y registros
...

Sheet Hoja2
B2: Assets
B3: Vulnerabilities
B4: Office rooms / facilities | C4: =_xlfn.TRANSLATE(B4,"en","es") -> Oficinas / instalaciones
B5: Lack of / inadequate maintenance | C5: =_xlfn.TRANSLATE(B5,"en","es") -> Falta de mantenimiento o insuficiente
B6: Incompatible infrastructure | C6: =_xlfn.TRANSLATE(B6,"en","es") -> Infraestructura incompatible
B7: Lack of access controls to facilities, rooms or offices | C7: =_xlfn.TRANSLATE(B7,"en","es") -> Falta de controles de acceso a instalaciones, habitaciones u oficinas
B8: Inadequate infrastructure capacity | C8: =_xlfn.TRANSLATE(B8,"en","es") -> Capacidad de infraestructura insuficiente
B9: Inadequate infrastructure change control | C9: =_xlfn.TRANSLATE(B9,"en","es") -> Control inadecuado de cambios en infraestructuras
B10: Inadequate electrical cabling | C10: =_xlfn.TRANSLATE(B10,"en","es") -> Cableado eléctrico inadecuado
B11: Lack of / poor internal audit of infrastructure | C11: =_xlfn.TRANSLATE(B11,"en","es") -> Falta de / mala auditoría interna de la infraestructura
B12: Location of infrastructure sensitive to natural disasters | C12: =_xlfn.TRANSLATE(B12,"en","es") -> Ubicación de infraestructuras sensibles a desastres naturales
B13: Location of infrastructure sensitive to water leakage | C13: =_xlfn.TRANSLATE(B13,"en","es") -> Ubicación de la infraestructura sensible a fugas de agua
B14: Over-dependence on one infrastructure | C14: =_xlfn.TRANSLATE(B14,"en","es") -> Sobredependencia de una sola infraestructura
B15: Rules related to infrastructure not clearly defined | C15: =_xlfn.TRANSLATE(B15,"en","es") -> Normas relacionadas con infraestructuras no claramente definidas
... B206: Continue | C206: =_xlfn.TRANSLATE(B206,"en","es") -> Continúa

Sheet Assets-Vulnera
A1: Assets
A2: Padre | B2: hijo | C2: Traducido | E2: Vulnerabilidades | F2: Traducido | I2: Amenazas | J2: Traducido
A3: Office adm | B3: Office rooms / facilities | C3: =_xlfn.TRANSLATE(B3,"en","es") -> Oficinas / instalaciones | E3: Access rights are granted beyond what is necessary | F3: =_xlfn.TRANSLATE(E3,"en","es") -> Los derechos de acceso se conceden más allá de lo necesario | I3: Access to information system with malicious intent | J3: =_xlfn.TRANSLATE(I3,"en","es") -> Sistema de acceso a la información con intención maliciosa
A4: Office adm | B4: Production facilities | C4: =_xlfn.TRANSLATE(B4,"en","es") -> Instalaciones de producción | E4: Assets | F4: =_xlfn.TRANSLATE(E4,"en","es") -> Activos | I4: Application error | J4: =_xlfn.TRANSLATE(I4,"en","es") -> Error de aplicación
A5: Office adm | B5: Infrastructure cabling (e.g., electrical, grounding, etc.) | C5: =_xlfn.TRANSLATE(B5,"en","es") -> Cableado de infraestructuras (por ejemplo, eléctrico, de puesta a tierra, etc.) | E5: Assets remain with suppliers/partners after the end of relationship | F5: =_xlfn.TRANSLATE(E5,"en","es") -> Los activos permanecen en manos de proveedores/socios tras el fin de la relación | I5: Attack through outsourced equipment/service (compromising supply chain) | J5: =_xlfn.TRANSLATE(I5,"en","es") -> Ataque a través de equipo/servicio externalizado (comprometiendo la cadena de suministro)
A6: Office adm | B6: Basic services (e.g., electricity, water, sewer, HVAC, air-conditioning, fire suppression, etc.) | C6: =_xlfn.TRANSLATE(B6,"en","es") -> Servicios básicos (por ejemplo, electricidad, agua, alcantarillado, climatización, aire acondicionado, supresión de incendios, etc.) | E6: Backup does not exist or is not regularly performed | F6: =_xlfn.TRANSLATE(E6,"en","es") -> No existe respaldo ni se realiza regularmente | I6: Breach of contracts or agreements | J6: =_xlfn.TRANSLATE(I6,"en","es") -> Incumplimiento de contratos o acuerdos
A7: Office adm | B7: Server room or datacenter | C7: =_xlfn.TRANSLATE(B7,"en","es") -> Sala de servidores o centro de datos | E7: Complicated user interface | F7: =_xlfn.TRANSLATE(E7,"en","es") -> Interfaz de usuario complicada | I7: Breach of laws or regulations | J7: =_xlfn.TRANSLATE(I7,"en","es") -> Incumplimiento de leyes o reglamentos
A8: Office adm | B8: Remote workspace | C8: =_xlfn.TRANSLATE(B8,"en","es") -> Espacio de trabajo remoto | E8: Confidentiality level not clearly defined | F8: =_xlfn.TRANSLATE(E8,"en","es") -> Nivel de confidencialidad no claramente definido | I8: Breakdown of communication links | J8: =_xlfn.TRANSLATE(I8,"en","es") -> Ruptura de los enlaces de comunicación
A9: Office adm | B9: Archives | C9: =_xlfn.TRANSLATE(B9,"en","es") -> Archivos | E9: Cryptographic keys accessible to unauthorized persons | F9: =_xlfn.TRANSLATE(E9,"en","es") -> Claves criptográficas accesibles para personas no autorizadas | I9: Concealing user identity | J9: =_xlfn.TRANSLATE(I9,"en","es") -> Ocultación de la identidad del usuario
A10: Office adm | B10: Warehouses | C10: =_xlfn.TRANSLATE(B10,"en","es") -> Almacenes | E10: Disposal of storage media without erasing data | F10: =_xlfn.TRANSLATE(E10,"en","es") -> Eliminación de medios de almacenamiento sin borrar datos | I10: Data / information theft | J10: =_xlfn.TRANSLATE(I10,"en","es") -> Robo de datos / información
A11: Office adm | B11: Safes | C11: =_xlfn.TRANSLATE(B11,"en","es") -> Cajas fuertes | E11: Downloads from Internet not controlled | F11: =_xlfn.TRANSLATE(E11,"en","es") -> Descargas de Internet no controladas | I11: Denial of service attack | J11: =_xlfn.TRANSLATE(I11,"en","es") -> Ataque de denegación de servicio
A12: Office adm | B12: Cabinets | C12: =_xlfn.TRANSLATE(B12,"en","es") -> Gabinetes | E12: Inadequate / incompatible equipment | F12: =_xlfn.TRANSLATE(E12,"en","es") -> Equipamiento inadecuado / incompatible | I12: Earthquake | J12: =_xlfn.TRANSLATE(I12,"en","es") -> Terremoto
A13: Office adm | B13: Uniterruptible power supply (UPS) devices | C13: =_xlfn.TRANSLATE(B13,"en","es") -> Dispositivos de alimentación unitrrumpible (SAI) | E13: Inadequate capacity of IT / communication equipment | F13: =_xlfn.TRANSLATE(E13,"en","es") -> Capacidad insuficiente de equipos de TI / comunicación | I13: Eavesdroppng | J13: =_xlfn.TRANSLATE(I13,"en","es") -> Escuchar a escondidas.
A14: Office adm | B14: Power generators | C14: =_xlfn.TRANSLATE(B14,"en","es") -> Generadores eléctricos | E14: Inadequate change control of documents and data | F14: =_xlfn.TRANSLATE(E14,"en","es") -> Control inadecuado de cambios en documentos y datos | I14: Equipment failure | J14: =_xlfn.TRANSLATE(I14,"en","es") -> Fallo del equipo
... A50: Human resources | B50: Employees with specific expertise (e.g. system administrators, designers, software developers, security experts, etc.) | C50: =_xlfn.TRANSLATE(B50,"en","es") -> Empleados con experiencia específica (por ejemplo, administradores de sistemas, diseñadores, desarrolladores de software, expertos en seguridad, etc.) | E50: Mobile equipment inadequately physically protected | F50: =_xlfn.TRANSLATE(E50,"en","es") -> Equipos móviles inadecuadamente protegidos físicamente | I50: Use of unauthorized or untested code with malicious intent | J50: =_xlfn.TRANSLATE(I50,"en","es") -> Uso de código no autorizado o no probado con intención maliciosa
A51: Human resources | B51: Middle management | C51: =_xlfn.TRANSLATE(B51,"en","es") -> Dirección intermedia | E51: Network devices inadequately physically protected | F51: =_xlfn.TRANSLATE(E51,"en","es") -> Dispositivos de red están insuficientemente protegidos físicamente | J51: {=+MAX(LEN(J3:J50))} -> 89
A52: Third-party services | B52: Power supply (electricity) | C52: =_xlfn.TRANSLATE(B52,"en","es") -> Suministro eléctrico (electricidad) | E52: No deactivation of user accounts after termination of employment | F52: =_xlfn.TRANSLATE(E52,"en","es") -> No se permiten desactivaciones de cuentas de usuario tras el terminamiento del contrato
A53: Third-party services | B53: Third-party services used over the Internet (e.g., SaaS) | C53: =_xlfn.TRANSLATE(B53,"en","es") -> Servicios de terceros utilizados a través de Internet (por ejemplo, SaaS) | E53: Over-dependence on a supplier/partner | F53: =_xlfn.TRANSLATE(E53,"en","es") -> Dependencia excesiva de un proveedor o socio
A54: Third-party services | B54: Outsourced personnel (e.g., freelancers or contractors) | C54: =_xlfn.TRANSLATE(B54,"en","es") -> Personal externalizado (por ejemplo, autónomos o contratistas) | E54: Over-dependence on one device | F54: =_xlfn.TRANSLATE(E54,"en","es") -> Dependencia excesiva de un solo dispositivo
A55: Third-party services | B55: Cleaning and facilities maintenance | C55: =_xlfn.TRANSLATE(B55,"en","es") -> Limpieza y mantenimiento de instalaciones | E55: Over-dependence on one infrastructure | F55: =_xlfn.TRANSLATE(E55,"en","es") -> Sobredependencia de una sola infraestructura
A56: Third-party services | B56: Auditors, supervisory authorities | C56: =_xlfn.TRANSLATE(B56,"en","es") -> Auditores, autoridades supervisoras | E56: Over-dependence on one system | F56: =_xlfn.TRANSLATE(E56,"en","es") -> Sobredependencia de un sistema
A57: Third-party services | B57: Consultants | C57: =_xlfn.TRANSLATE(B57,"en","es") -> Consultores | E57: Poor selection of test data | F57: =_xlfn.TRANSLATE(E57,"en","es") -> Mala selección de datos de pruebas
A58: Third-party services | B58: Legal services | C58: =_xlfn.TRANSLATE(B58,"en","es") -> Servicios legales | E58: Replacement person does not exist / is inadequate | F58: =_xlfn.TRANSLATE(E58,"en","es") -> La persona de reemplazo no existe / es inadecuada
A59: Third-party services | B59: Mail and courier services | C59: =_xlfn.TRANSLATE(B59,"en","es") -> Servicios de correo y mensajería | E59: Requirements for software development not clearly defined | F59: =_xlfn.TRANSLATE(E59,"en","es") -> Requisitos para el desarrollo de software no claramente definidos
A60: Third-party services | B60: Software and database maintenance | C60: =_xlfn.TRANSLATE(B60,"en","es") -> Mantenimiento de software y bases de datos | E60: Rules for IT / communication equipment not clearly defined | F60: =_xlfn.TRANSLATE(E60,"en","es") -> Normas para equipos de TI / comunicaciones no claramente definidas
A61: Third-party services | B61: IT equipment maintenance | C61: =_xlfn.TRANSLATE(B61,"en","es") -> Mantenimiento de equipos informáticos | E61: Rules for software and its databases not clearly defined | F61: =_xlfn.TRANSLATE(E61,"en","es") -> Reglas para software y sus bases de datos no claramente definidas
A62: Third-party services | B62: Communication services (voice, Internet, etc.) | C62: =_xlfn.TRANSLATE(B62,"en","es") -> Servicios de comunicación (voz, Internet, etc.) | E62: Rules for working off-premises not clearly defined | F62: =_xlfn.TRANSLATE(E62,"en","es") -> Reglas para trabajar fuera de las instalaciones no claramente definidas
E63: Rules on document control not clearly defined | F63: =_xlfn.TRANSLATE(E63,"en","es") -> Reglas sobre el control de documentos no claramente definidas
C64: {=+MAX(LEN(C3:C62))} -> 150 | E64: Rules on how to handle information not clearly defined | F64: =_xlfn.TRANSLATE(E64,"en","es") -> Normas sobre cómo manejar información no claramente definidas
E65: Rules on how to handle third parties not clearly defined | F65: =_xlfn.TRANSLATE(E65,"en","es") -> Normas sobre cómo tratar a terceros no están claramente definidas
E66: Rules related to infrastructure not clearly defined | F66: =_xlfn.TRANSLATE(E66,"en","es") -> Normas relacionadas con infraestructuras no claramente definidas
E67: Sensitivity of equipment to humidity and pollution | F67: =_xlfn.TRANSLATE(E67,"en","es") -> Sensibilidad del equipo a la humedad y la contaminación
E68: Sensitivity of equipment to temperature | F68: =_xlfn.TRANSLATE(E68,"en","es") -> Sensibilidad del equipo a la temperatura
E69: Sensitivity of equipment to voltage change | F69: =_xlfn.TRANSLATE(E69,"en","es") -> Sensibilidad del equipo al cambio de tensión
E70: Sessions are left active after working hours | F70: =_xlfn.TRANSLATE(E70,"en","es") -> Las sesiones permanecen activas después del horario laboral
E71: Single copy / only one copy of information available | F71: =_xlfn.TRANSLATE(E71,"en","es") -> Copia única / solo una copia de la información disponible
E72: Software components not compatible | F72: =_xlfn.TRANSLATE(E72,"en","es") -> Componentes de software no compatibles
E73: Software design flaw | F73: =_xlfn.TRANSLATE(E73,"en","es") -> Fallo de diseño de software
E74: Software misconfiguration | F74: =_xlfn.TRANSLATE(E74,"en","es") -> Error de configuración del software
E75: System-generated passwords remain unchanged | F75: =_xlfn.TRANSLATE(E75,"en","es") -> Las contraseñas generadas por el sistema permanecen sin cambios
...

Sheet Hoja5
A3: Etiquetas de fila
A4: Access to information system with malicious intent
A5: Application error
A6: Attack through outsourced equipment/service (compromising supply chain)
A7: Breach of contracts or agreements
A8: Breach of laws or regulations
A9: Breakdown of communication links
A10: Concealing user identity
A11: Data / information theft
A12: Denial of service attack
A13: Earthquake
A14: Eavesdroppng
... A52: Total general

Sheet Combinaciones
B3: Infrastructure
B4: Assets
B5: Vulnerabilities
B6: Threats | C6: Assets | D6: Vulnerabilities | E6: Threats | F6: Id_rel | G6: id_act | H6: Activo | I6: id_vul | J6: Vulnerabilities | K6: id_ame | L6: Amenazas
B7: Office rooms / facilities | C7: Office rooms / facilities | D7: Lack of access controls to facilities, rooms or offices | E7: Manipulation or destruction of equipment | F7: 1 | G7: =+VLOOKUP(H7,Exportados!$H:$I,2,0) -> 2 | H7: =_xlfn.TRANSLATE(C7,"en","es") -> Oficinas / instalaciones | I7: =+VLOOKUP(J7,Exportados!$A:$B,2,0) -> 36 | J7: =_xlfn.TRANSLATE(D7,"en","es") -> Falta de controles de acceso a instalaciones, habitaciones u oficinas | K7: =+VLOOKUP(L7,Exportados!$D:$E,2,0) -> 29 | L7: =_xlfn.TRANSLATE(E7,"en","es") -> Manipulación o destrucción de equipos
B8: Lack of access controls to facilities, rooms or offices | C8: Office rooms / facilities | D8: Lack of access controls to facilities, rooms or offices | E8: Unauthorized entry into facilities, rooms or offices | G8: =+VLOOKUP(H8,Exportados!$H:$I,2,0) -> 2 | H8: =_xlfn.TRANSLATE(C8,"en","es") -> Oficinas / instalaciones | I8: =+VLOOKUP(J8,Exportados!$A:$B,2,0) -> 36 | J8: =_xlfn.TRANSLATE(D8,"en","es") -> Falta de controles de acceso a instalaciones, habitaciones u oficinas | K8: =+VLOOKUP(L8,Exportados!$D:$E,2,0) -> 36 | L8: =_xlfn.TRANSLATE(E8,"en","es") -> Entrada no autorizada en instalaciones, habitaciones u oficinas
B9: Manipulation or destruction of equipment | C9: Office rooms / facilities | D9: Lack of access controls to facilities, rooms or offices | E9: Theft, vandalism, or sabotage | G9: =+VLOOKUP(H9,Exportados!$H:$I,2,0) -> 2 | H9: =_xlfn.TRANSLATE(C9,"en","es") -> Oficinas / instalaciones | I9: =+VLOOKUP(J9,Exportados!$A:$B,2,0) -> 36 | J9: =_xlfn.TRANSLATE(D9,"en","es") -> Falta de controles de acceso a instalaciones, habitaciones u oficinas | K9: =+VLOOKUP(L9,Exportados!$D:$E,2,0) -> 34 | L9: =_xlfn.TRANSLATE(E9,"en","es") -> Robo, vandalismo o sabotaje
B10: Unauthorized entry into facilities, rooms or offices | C10: Office rooms / facilities | D10: Lack of access controls to facilities, rooms or offices | E10: Terrorist attack (bomb, shooting, etc.) | G10: =+VLOOKUP(H10,Exportados!$H:$I,2,0) -> 2 | H10: =_xlfn.TRANSLATE(C10,"en","es") -> Oficinas / instalaciones | I10: =+VLOOKUP(J10,Exportados!$A:$B,2,0) -> 36 | J10: =_xlfn.TRANSLATE(D10,"en","es") -> Falta de controles de acceso a instalaciones, habitaciones u oficinas | K10: =+VLOOKUP(L10,Exportados!$D:$E,2,0) -> 33 | L10: =_xlfn.TRANSLATE(E10,"en","es") -> Atentado terrorista (bomba, tiroteo, etc.)
B11: Theft, vandalism, or sabotage | C11: Server room or datacenter | D11: Lack of / poor internal audit of infrastructure | E11: Fire | G11: =+VLOOKUP(H11,Exportados!$H:$I,2,0) -> 6 | H11: =_xlfn.TRANSLATE(C11,"en","es") -> Sala de servidores o centro de datos | I11: =+VLOOKUP(J11,Exportados!$A:$B,2,0) -> 33 | J11: =_xlfn.TRANSLATE(D11,"en","es") -> Falta de / mala auditoría interna de la infraestructura | K11: =+VLOOKUP(L11,Exportados!$D:$E,2,0) -> 15 | L11: =_xlfn.TRANSLATE(E11,"en","es") -> Incendio
B12: Terrorist attack (bomb, shooting, etc.) | C12: Server room or datacenter | D12: Lack of / poor internal audit of infrastructure | E12: Flood | G12: =+VLOOKUP(H12,Exportados!$H:$I,2,0) -> 6 | H12: =_xlfn.TRANSLATE(C12,"en","es") -> Sala de servidores o centro de datos | I12: =+VLOOKUP(J12,Exportados!$A:$B,2,0) -> 33 | J12: =_xlfn.TRANSLATE(D12,"en","es") -> Falta de / mala auditoría interna de la infraestructura | K12: =+VLOOKUP(L12,Exportados!$D:$E,2,0) -> 16 | L12: =_xlfn.TRANSLATE(E12,"en","es") -> Inundación
B13: Server room or datacenter | C13: Server room or datacenter | D13: Lack of / poor internal audit of infrastructure | E13: Other disasters (natural) | G13: =+VLOOKUP(H13,Exportados!$H:$I,2,0) -> 6 | H13: =_xlfn.TRANSLATE(C13,"en","es") -> Sala de servidores o centro de datos | I13: =+VLOOKUP(J13,Exportados!$A:$B,2,0) -> 33 | J13: =_xlfn.TRANSLATE(D13,"en","es") -> Falta de / mala auditoría interna de la infraestructura | K13: =+VLOOKUP(L13,Exportados!$D:$E,2,0) -> 31 | L13: =_xlfn.TRANSLATE(E13,"en","es") -> Otros desastres (naturales)
B14: Lack of / poor internal audit of infrastructure | C14: Server room or datacenter | D14: Lack of / poor internal audit of infrastructure | E14: Lightning strike | G14: =+VLOOKUP(H14,Exportados!$H:$I,2,0) -> 6 | H14: =_xlfn.TRANSLATE(C14,"en","es") -> Sala de servidores o centro de datos | I14: =+VLOOKUP(J14,Exportados!$A:$B,2,0) -> 33 | J14: =_xlfn.TRANSLATE(D14,"en","es") -> Falta de / mala auditoría interna de la infraestructura | K14: =+VLOOKUP(L14,Exportados!$D:$E,2,0) -> 24 | L14: =_xlfn.TRANSLATE(E14,"en","es") -> Rayo
B15: Fire | C15: Server room or datacenter | D15: Lack of / poor internal audit of infrastructure | E15: Earthquake | G15: =+VLOOKUP(H15,Exportados!$H:$I,2,0) -> 6 | H15: =_xlfn.TRANSLATE(C15,"en","es") -> Sala de servidores o centro de datos | I15: =+VLOOKUP(J15,Exportados!$A:$B,2,0) -> 33 | J15: =_xlfn.TRANSLATE(D15,"en","es") -> Falta de / mala auditoría interna de la infraestructura | K15: =+VLOOKUP(L15,Exportados!$D:$E,2,0) -> 10 | L15: =_xlfn.TRANSLATE(E15,"en","es") -> Terremoto
B16: Flood | C16: Server room or datacenter | D16: Lack of / poor internal audit of infrastructure | E16: Storm | G16: =+VLOOKUP(H16,Exportados!$H:$I,2,0) -> 6 | H16: =_xlfn.TRANSLATE(C16,"en","es") -> Sala de servidores o centro de datos | I16: =+VLOOKUP(J16,Exportados!$A:$B,2,0) -> 33 | J16: =_xlfn.TRANSLATE(D16,"en","es") -> Falta de / mala auditoría interna de la infraestructura | K16: =+VLOOKUP(L16,Exportados!$D:$E,2,0) -> 32 | L16: =_xlfn.TRANSLATE(E16,"en","es") -> Tormenta
B17: Other disasters (natural) | C17: Server room or datacenter | D17: Lack of / poor internal audit of infrastructure | E17: Industrial accident | G17: =+VLOOKUP(H17,Exportados!$H:$I,2,0) -> 6 | H17: =_xlfn.TRANSLATE(C17,"en","es") -> Sala de servidores o centro de datos | I17: =+VLOOKUP(J17,Exportados!$A:$B,2,0) -> 33 | J17: =_xlfn.TRANSLATE(D17,"en","es") -> Falta de / mala auditoría interna de la infraestructura | K17: =+VLOOKUP(L17,Exportados!$D:$E,2,0) -> 19 | L17: =_xlfn.TRANSLATE(E17,"en","es") -> Accidente industrial
B18: Lightning strike | C18: Server room or datacenter | D18: Lack of / poor internal audit of infrastructure | E18: Interruption of communication services | G18: =+VLOOKUP(H18,Exportados!$H:$I,2,0) -> 6 | H18: =_xlfn.TRANSLATE(C18,"en","es") -> Sala de servidores o centro de datos | I18: =+VLOOKUP(J18,Exportados!$A:$B,2,0) -> 33 | J18: =_xlfn.TRANSLATE(D18,"en","es") -> Falta de / mala auditoría interna de la infraestructura | K18: =+VLOOKUP(L18,Exportados!$D:$E,2,0) -> 23 | L18: =_xlfn.TRANSLATE(E18,"en","es") -> Interrupción de los servicios de comunicación
B19: Earthquake | C19: Desktop computers | D19: Mobile equipment inadequately physically protected | E19: Manipulation or destruction of equipment | G19: =+VLOOKUP(H19,Exportados!$H:$I,2,0) -> 19 | H19: =_xlfn.TRANSLATE(C19,"en","es") -> Ordenadores de sobremesa | I19: =+VLOOKUP(J19,Exportados!$A:$B,2,0) -> 48 | J19: =_xlfn.TRANSLATE(D19,"en","es") -> Equipos móviles inadecuadamente protegidos físicamente | K19: =+VLOOKUP(L19,Exportados!$D:$E,2,0) -> 29 | L19: =_xlfn.TRANSLATE(E19,"en","es") -> Manipulación o destrucción de equipos
... B98: Lack of evidence of sent or received messages | C98: Communication services (voice, Internet, etc.) | D98: Lack of control on where third-party stores information | E98: Attack through outsourced equipment/service (compromising supply chain) | G98: =+VLOOKUP(H98,Exportados!$H:$I,2,0) -> 61 | H98: =_xlfn.TRANSLATE(C98,"en","es") -> Servicios de comunicación (voz, Internet, etc.) | I98: =+VLOOKUP(J98,Exportados!$A:$B,2,0) -> 38 | J98: =_xlfn.TRANSLATE(D98,"en","es") -> Falta de control sobre dónde almacena la información de terceros | K98: =+VLOOKUP(L98,Exportados!$D:$E,2,0) -> 3 | L98: =_xlfn.TRANSLATE(E98,"en","es") -> Ataque a través de equipo/servicio externalizado (comprometiendo la cadena de suministro)
B99: Application error
B100: Lack of validation for processed data
B101: Breach of contracts or agreements
B102: Unintentional change of data in an information system
B103: Malicious user error
B104: Application error
B105: Other documents and data (in electronic and other forms)
B106: Assets
B107: Vulnerabilities
B108: Threats
B109: Personal data (e.g., from employees or customers)
B110: Wrong understanding about the sensitivity of information
... B151: Complete the excercise

Sheet Exportados
A1: nombre_vul | B1: id | D1: nombre_ame | E1: id | H1: nombre_act | I1: id
A2: Los derechos de acceso se conceden más allá de lo necesario | B2: 1 | D2: Sistema de acceso a la información con intención maliciosa | E2: 1 | H2: Activos | I2: 1
A3: Activos | B3: 2 | D3: Error de aplicación | E3: 2 | H3: Oficinas / instalaciones | I3: 2
A4: Los activos permanecen en manos de proveedores/socios tras el fin de la relación | B4: 3 | D4: Ataque a través de equipo/servicio externalizado (comprometiendo la cadena de suministro) | E4: 3 | H4: Instalaciones de producción | I4: 3
A5: No existe respaldo ni se realiza regularmente | B5: 4 | D5: Incumplimiento de contratos o acuerdos | E5: 4 | H5: Cableado de infraestructuras (por ejemplo, eléctrico, de puesta a tierra, etc.) | I5: 4
A6: Interfaz de usuario complicada | B6: 5 | D6: Incumplimiento de leyes o reglamentos | E6: 5 | H6: Servicios básicos (por ejemplo, electricidad, agua, alcantarillado, climatización, aire acondicionado, supresión de incendios, etc.) | I6: 5
A7: Nivel de confidencialidad no claramente definido | B7: 6 | D7: Ruptura de los enlaces de comunicación | E7: 6 | H7: Sala de servidores o centro de datos | I7: 6
A8: Claves criptográficas accesibles para personas no autorizadas | B8: 7 | D8: Ocultación de la identidad del usuario | E8: 7 | H8: Espacio de trabajo remoto | I8: 7
A9: Eliminación de medios de almacenamiento sin borrar datos | B9: 8 | D9: Robo de datos / información | E9: 8 | H9: Archivos | I9: 8
A10: Descargas de Internet no controladas | B10: 9 | D10: Ataque de denegación de servicio | E10: 9 | H10: Almacenes | I10: 9
A11: Equipamiento inadecuado / incompatible | B11: 10 | D11: Terremoto | E11: 10 | H11: Cajas fuertes | I11: 10
A12: Capacidad insuficiente de equipos de TI / comunicación | B12: 11 | D12: Escuchar a escondidas. | E12: 11 | H12: Gabinetes | I12: 11
A13: Control inadecuado de cambios en documentos y datos | B13: 12 | D13: Fallo del equipo | E13: 12 | H13: Dispositivos de alimentación unitrrumpible (SAI) | I13: 12
... A49: Equipos móviles inadecuadamente protegidos físicamente | B49: 48 | D49: Uso de código no autorizado o no probado con intención maliciosa | E49: 48 | H49: Empleados remotos | I49: 48
A50: Dispositivos de red están insuficientemente protegidos físicamente | B50: 49 | H50: Empleados con experiencia específica (por ejemplo, administradores de sistemas, diseñadores, desarrolladores de software, expertos en seguridad, etc.) | I50: 49
A51: No se permiten desactivaciones de cuentas de usuario tras el terminamiento del contrato | B51: 50 | H51: Dirección intermedia | I51: 50
A52: Dependencia excesiva de un proveedor o socio | B52: 51 | H52: Suministro eléctrico (electricidad) | I52: 51
A53: Dependencia excesiva de un solo dispositivo | B53: 52 | H53: Servicios de terceros utilizados a través de Internet (por ejemplo, SaaS) | I53: 52
A54: Sobredependencia de una sola infraestructura | B54: 53 | H54: Personal externalizado (por ejemplo, autónomos o contratistas) | I54: 53
A55: Sobredependencia de un sistema | B55: 54 | H55: Limpieza y mantenimiento de instalaciones | I55: 54
A56: Mala selección de datos de pruebas | B56: 55 | H56: Auditores, autoridades supervisoras | I56: 55
A57: La persona de reemplazo no existe / es inadecuada | B57: 56 | H57: Consultores | I57: 56
A58: Requisitos para el desarrollo de software no claramente definidos | B58: 57 | H58: Servicios legales | I58: 57
A59: Normas para equipos de TI / comunicaciones no claramente definidas | B59: 58 | H59: Servicios de correo y mensajería | I59: 58
A60: Reglas para software y sus bases de datos no claramente definidas | B60: 59 | H60: Mantenimiento de software y bases de datos | I60: 59
A61: Reglas para trabajar fuera de las instalaciones no claramente definidas | B61: 60 | H61: Mantenimiento de equipos informáticos | I61: 60
A62: Reglas sobre el control de documentos no claramente definidas | B62: 61 | H62: Servicios de comunicación (voz, Internet, etc.) | I62: 61
A63: Normas sobre cómo manejar información no claramente definidas | B63: 62
A64: Normas sobre cómo tratar a terceros no están claramente definidas | B64: 63
A65: Normas relacionadas con infraestructuras no claramente definidas | B65: 64
A66: Sensibilidad del equipo a la humedad y la contaminación | B66: 65
A67: Sensibilidad del equipo a la temperatura | B67: 66
A68: Sensibilidad del equipo al cambio de tensión | B68: 67
A69: Las sesiones permanecen activas después del horario laboral | B69: 68
A70: Copia única / solo una copia de la información disponible | B70: 69
A71: Componentes de software no compatibles | B71: 70
A72: Fallo de diseño de software | B72: 71
A73: Error de configuración del software | B73: 72
A74: Las contraseñas generadas por el sistema permanecen sin cambios | B74: 73
... A88: Comprensión errónea sobre la sensibilidad de la información | B88: 87
